Workbook

Sheet صورت‌حساب
A2: صورت‌حساب سپرده | B2: 9316-888-1512735-1 | D2: از 1404/07/01 - 00:00 تا 1404/07/30 - 23:59
A3: IR330560931688801512735001 | D3: تاریخ ایجاد گزارش: 1404/08/16 - 22:30
A4: شعبه تهیه گزارش: اینترنت بانک
B5: ارز سپرده: | C5: ریال | D5: موجودی: | E5: 99584637 | F5: موجودی قابل برداشت: | G5: 99584637 | H5: مبلغ مسدودی: | J5: 0
B6: شناسه واریز: | D6: ترتیب تاریخ: | E6: صعودی | F6: نوع تراکنش:
B7: از مبلغ: | D7: تا مبلغ: | F7: یادداشت:
A8: ردیف | B8: تاریخ | C8: زمان | D8: عملیات | E8: شرح | F8: واریز (ریال) | G8: برداشت (ریال) | H8: مانده (ریال) | I8: شماره کارت | J8: شعبه | K8: شماره سند | L8: شماره برگه/شماره چک | M8: شناسه واریز | N8: یادداشت | O8: شماره پیگیری
A9: 1 | B9: 1404/07/01 | C9: 07:02:36 | D9: انتقال وجه از طريق مدرن | E9: انتقال وجه موبايلت از سپرده 9316.888.1579090.1 ش.پ 00001758598356202052 - محمود ابراهيميان | F9: 140000000 | G9: 0 | H9: 161867925 | I9: =IFERROR(__xludf.DUMMYFUNCTION("REGEXEXTRACT(E9, ""ک\s(\d{16})"")"),"#N/A") -> #N/A | J9: نيشابور(9316) | K9: 50864603 | L9: - | O9: 00001758598356202052
A10: 2 | B10: 1404/07/01 | C10: 07:12:43 | D10: انتقال وجه از طريق مدرن | E10: انتقال وجه موبايلت از سپرده 9316.888.1579090.1 ش.پ 00001758598963401925 - محمود ابراهيميان | F10: 7900000 | G10: 0 | H10: 169767925 | I10: =IFERROR(__xludf.DUMMYFUNCTION("REGEXEXTRACT(E10, ""ک\s(\d{16})"")"),"#N/A") -> #N/A | J10: نيشابور(9316) | K10: 10864048 | L10: - | O10: 00001758598963401925
A11: 3 | B11: 1404/07/01 | C11: 11:17:48 | D11: خريد کالا | E11: خريد کالا و خدمات از پايانه فروش 14973164 پرداخت الکترونيک سامان1 از ک 6219861085979838 ش م 85472825 | F11: 0 | G11: 33435000 | H11: 136332925 | I11: =IFERROR(__xludf.DUMMYFUNCTION("REGEXEXTRACT(E11, ""ک\s(\d{16})"")"),"6219861085979838") -> 6219861085979838 | J11: مرکز عمليات کارت(880) | K11: 30870342 | L11: -
A12: 4 | B12: 1404/07/01 | C12: 11:57:56 | D12: انتقال وجه داخلي | E12: انتقال از خودپرداز 45101693 تجارت - بين 2 به ک 6037701575716284 ش م 169326543071 ش پ 169373 | F12: 0 | G12: 30000000 | H12: 106332925 | I12: =IFERROR(__xludf.DUMMYFUNCTION("REGEXEXTRACT(E12, ""ک\s(\d{16})"")"),"6037701575716284") -> 6037701575716284 | J12: مرکز عمليات کارت(880) | K12: 40871671 | L12: -
A13: 5 | B13: 1404/07/01 | C13: 11:57:56 | D13: انتقال وجه داخلي | E13: کارمزد انتقال از خودپرداز 45101693 تجارت - بين 2 از ک 6219861085979838 ش م 169326543071 ش پ 169373 | F13: 0 | G13: 15400 | H13: 106317525 | I13: =IFERROR(__xludf.DUMMYFUNCTION("REGEXEXTRACT(E13, ""ک\s(\d{16})"")"),"6219861085979838") -> 6219861085979838 | J13: مرکز عمليات کارت(880) | K13: 40871671 | L13: -
A14: 6 | B14: 1404/07/01 | C14: 11:58:27 | D14: انتقال وجه داخلي | E14: انتقال از خودپرداز 45101693 تجارت - بين 2 به ک 6104338738476148 ش م 169326543105 ش پ 169374 | F14: 0 | G14: 19824600 | H14: 86492925 | I14: =IFERROR(__xludf.DUMMYFUNCTION("REGEXEXTRACT(E14, ""ک\s(\d{16})"")"),"6104338738476148") -> 6104338738476148 | J14: مرکز عمليات کارت(880) | K14: 30871525 | L14: -
A15: 7 | B15: 1404/07/01 | C15: 11:58:27 | D15: انتقال وجه داخلي | E15: کارمزد انتقال از خودپرداز 45101693 تجارت - بين 2 از ک 6219861085979838 ش م 169326543105 ش پ 169374 | F15: 0 | G15: 12200 | H15: 86480725 | I15: =IFERROR(__xludf.DUMMYFUNCTION("REGEXEXTRACT(E15, ""ک\s(\d{16})"")"),"6219861085979838") -> 6219861085979838 | J15: مرکز عمليات کارت(880) | K15: 30871525 | L15: -
A16: 8 | B16: 1404/07/01 | C16: 11:58:53 | D16: انتقال وجه داخلي | E16: انتقال از خودپرداز 45101693 تجارت - بين 2 به ک 6274121208660688 ش م 169326543131 ش پ 169375 | F16: 0 | G16: 28170000 | H16: 58310725 | I16: =IFERROR(__xludf.DUMMYFUNCTION("REGEXEXTRACT(E16, ""ک\s(\d{16})"")"),"6274121208660688") -> 6274121208660688 | J16: مرکز عمليات کارت(880) | K16: 40871680 | L16: -
A17: 9 | B17: 1404/07/01 | C17: 11:58:53 | D17: انتقال وجه داخلي | E17: کارمزد انتقال از خودپرداز 45101693 تجارت - بين 2 از ک 6219861085979838 ش م 169326543131 ش پ 169375 | F17: 0 | G17: 15400 | H17: 58295325 | I17: =IFERROR(__xludf.DUMMYFUNCTION("REGEXEXTRACT(E17, ""ک\s(\d{16})"")"),"6219861085979838") -> 6219861085979838 | J17: مرکز عمليات کارت(880) | K17: 40871680 | L17: -
A18: 10 | B18: 1404/07/01 | C18: 12:02:56 | D18: اعلام موجودي | E18: کارمزد مانده حساب از پايانه فروش 13444162 پرداخت الکترونيک سامان1 از ک 6219861085979838 ش م 85473011 | F18: 0 | G18: 1800 | H18: 58293525 | I18: =IFERROR(__xludf.DUMMYFUNCTION("REGEXEXTRACT(E18, ""ک\s(\d{16})"")"),"6219861085979838") -> 6219861085979838 | J18: مرکز عمليات کارت(880) | K18: 30871583 | L18: -
A19: 11 | B19: 1404/07/01 | C19: 13:33:33 | D19: خريد کالا | E19: خريد کالا و خدمات از پايانه فروش 05465898 کارت اعتباري ايران کيش از ک 6219861085979838 ش م 658982650 | F19: 0 | G19: 2350000 | H19: 55943525 | I19: =IFERROR(__xludf.DUMMYFUNCTION("REGEXEXTRACT(E19, ""ک\s(\d{16})"")"),"6219861085979838") -> 6219861085979838 | J19: مرکز عمليات کارت(880) | K19: 40875262 | L19: -
A20: 12 | B20: 1404/07/01 | C20: 20:00:53 | D20: انتقال وجه داخلي | E20: انتقال از اينترنت I000MP01 تجارت - بين 2 از ک 5859831105862774 ش م 136232302991 ش پ 187674 | F20: 250000 | G20: 0 | H20: 56193525 | I20: =IFERROR(__xludf.DUMMYFUNCTION("REGEXEXTRACT(E20, ""ک\s(\d{16})"")"),"5859831105862774") -> 5859831105862774 | J20: مرکز عمليات کارت(880) | K20: 30885576 | L20: -
A21: 13 | B21: 1404/07/02 | C21: 04:47:21 | D21: انتقال وجه از طريق مدرن | E21: انتقال وجه موبايلت از سپرده 9316.888.1579090.1 ش.پ 00001758676641322350 - محمود ابراهيميان | F21: 40000000 | G21: 0 | H21: 96193525 | I21: =IFERROR(__xludf.DUMMYFUNCTION("REGEXEXTRACT(E21, ""ک\s(\d{16})"")"),"#N/A") -> #N/A | J21: نيشابور(9316) | K21: 20886873 | L21: - | O21: 00001758676641322350
A22: 14 | B22: 1404/07/02 | C22: 04:48:14 | D22: انتقال وجه از طريق مدرن | E22: انتقال وجه موبايلت از سپرده 9316.888.1579090.1 ش.پ 00001758676694053361 - محمود ابراهيميان | F22: 28000000 | G22: 0 | H22: 124193525 | I22: =IFERROR(__xludf.DUMMYFUNCTION("REGEXEXTRACT(E22, ""ک\s(\d{16})"")"),"#N/A") -> #N/A | J22: نيشابور(9316) | K22: 10891266 | L22: - | O22: 00001758676694053361
A23: 15 | B23: 1404/07/02 | C23: 09:27:50 | D23: خريد کالا | E23: خريد کالا و خدمات از پايانه فروش 33562616 پرداخت الکترونيک سداد 2 از ک 6219861085979838 ش م 32885947 | F23: 0 | G23: 15600000 | H23: 108593525 | I23: =IFERROR(__xludf.DUMMYFUNCTION("REGEXEXTRACT(E23, ""ک\s(\d{16})"")"),"6219861085979838") -> 6219861085979838 | J23: مرکز عمليات کارت(880) | K23: 30895836 | L23: -
A24: 16 | B24: 1404/07/02 | C24: 09:45:12 | D24: خريد کالا | E24: خريد کالا و خدمات از پايانه فروش 33795243 پرداخت الکترونيک سداد 2 از ک 6219861085979838 ش م 32885969 | F24: 0 | G24: 10000000 | H24: 98593525 | I24: =IFERROR(__xludf.DUMMYFUNCTION("REGEXEXTRACT(E24, ""ک\s(\d{16})"")"),"6219861085979838") -> 6219861085979838 | J24: مرکز عمليات کارت(880) | K24: 30895981 | L24: -
A25: 17 | B25: 1404/07/02 | C25: 09:50:22 | D25: خريد کالا | E25: خريد کالا و خدمات از پايانه فروش 07027865 کارت اعتباري ايران کيش از ک 6219861085979838 ش م 278652666 | F25: 0 | G25: 14885000 | H25: 83708525 | I25: =IFERROR(__xludf.DUMMYFUNCTION("REGEXEXTRACT(E25, ""ک\s(\d{16})"")"),"6219861085979838") -> 6219861085979838 | J25: مرکز عمليات کارت(880) | K25: 40896464 | L25: -
A26: 18 | B26: 1404/07/02 | C26: 10:50:22 | D26: خريد کالا | E26: خريد کالا و خدمات از پايانه فروش 99085527 مبنا کارت آريا (اينفوتک) از ک 6219861085979838 ش م 1290901 | F26: 0 | G26: 10375000 | H26: 73333525 | I26: =IFERROR(__xludf.DUMMYFUNCTION("REGEXEXTRACT(E26, ""ک\s(\d{16})"")"),"6219861085979838") -> 6219861085979838 | J26: مرکز عمليات کارت(880) | K26: 40898473 | L26: -
A27: 19 | B27: 1404/07/02 | C27: 11:56:33 | D27: صدور سند انتقال | E27: انتقال وجه بلو بانک از شبا IR810560611828005612979301 ش.پ 14042912609274 - مبينا دادگري | F27: 1150000 | G27: 0 | H27: 74483525 | I27: =IFERROR(__xludf.DUMMYFUNCTION("REGEXEXTRACT(E27, ""ک\s(\d{16})"")"),"#N/A") -> #N/A | J27: مرکزي(802) | K27: 10899152 | L27: -
A28: 20 | B28: 1404/07/02 | C28: 12:12:34 | D28: خريد کالا | E28: خريد کالا و خدمات از پايانه فروش 10073665 پرداخت الکترونيک سامان1 از ک 6219861085979838 ش م 85476458 | F28: 0 | G28: 6000000 | H28: 68483525 | I28: =IFERROR(__xludf.DUMMYFUNCTION("REGEXEXTRACT(E28, ""ک\s(\d{16})"")"),"6219861085979838") -> 6219861085979838 | J28: مرکز عمليات کارت(880) | K28: 40901487 | L28: -
A29: 21 | B29: 1404/07/02 | C29: 12:55:19 | D29: اعلام موجودي | E29: کارمزد مانده حساب از پايانه فروش 13444162 پرداخت الکترونيک سامان1 از ک 6219861085979838 ش م 85476631 | F29: 0 | G29: 1800 | H29: 68481725 | I29: =IFERROR(__xludf.DUMMYFUNCTION("REGEXEXTRACT(E29, ""ک\s(\d{16})"")"),"6219861085979838") -> 6219861085979838 | J29: مرکز عمليات کارت(880) | K29: 30903437 | L29: -
A30: 22 | B30: 1404/07/02 | C30: 13:24:22 | D30: انتقال وجه داخلي | E30: انتقال از اينترنت I000MP01 تجارت - بين 2 از ک 5859831227346631 ش م 984881868405 ش پ 183289 | F30: 150000 | G30: 0 | H30: 68631725 | I30: =IFERROR(__xludf.DUMMYFUNCTION("REGEXEXTRACT(E30, ""ک\s(\d{16})"")"),"5859831227346631") -> 5859831227346631 | J30: مرکز عمليات کارت(880) | K30: 30904353 | L30: -
A31: 23 | B31: 1404/07/02 | C31: 19:00:11 | D31: انتقال وجه داخلي | E31: انتقال از اينترنت 00019041 سامان به ک 6037701642636788 ش م 526719070517 ش پ 070517 | F31: 0 | G31: 13200000 | H31: 55431725 | I31: =IFERROR(__xludf.DUMMYFUNCTION("REGEXEXTRACT(E31, ""ک\s(\d{16})"")"),"6037701642636788") -> 6037701642636788 | J31: مرکز عمليات کارت(880) | K31: 40912244 | L31: -
A32: 24 | B32: 1404/07/02 | C32: 19:00:11 | D32: انتقال وجه داخلي | E32: کارمزد انتقال از اينترنت 00019041 سامان از ک 6219861085979838 ش م 526719070517 ش پ 070517 | F32: 0 | G32: 12200 | H32: 55419525 | I32: =IFERROR(__xludf.DUMMYFUNCTION("REGEXEXTRACT(E32, ""ک\s(\d{16})"")"),"6219861085979838") -> 6219861085979838 | J32: مرکز عمليات کارت(880) | K32: 40912244 | L32: -
A33: 25 | B33: 1404/07/03 | C33: 06:01:8 | D33: انتقال وجه از طريق مدرن | E33: انتقال وجه موبايلت از سپرده 9316.888.1579090.1 ش.پ 00001758767468899694 - محمود ابراهيميان | F33: 72000000 | G33: 0 | H33: 127419525 | I33: =IFERROR(__xludf.DUMMYFUNCTION("REGEXEXTRACT(E33, ""ک\s(\d{16})"")"),"#N/A") -> #N/A | J33: نيشابور(9316) | K33: 50915482 | L33: - | O33: 00001758767468899694
A34: 26 | B34: 1404/07/03 | C34: 10:00:19 | D34: خريد کالا | E34: خريد کالا و خدمات از پايانه فروش 33576242 پرداخت الکترونيک سداد 2 از ک 6219861085979838 ش م 32887403 | F34: 0 | G34: 2000000 | H34: 125419525 | I34: =IFERROR(__xludf.DUMMYFUNCTION("REGEXEXTRACT(E34, ""ک\s(\d{16})"")"),"6219861085979838") -> 6219861085979838 | J34: مرکز عمليات کارت(880) | K34: 40925822 | L34: -
A35: 27 | B35: 1404/07/03 | C35: 11:30:56 | D35: انتقال وجه داخلي | E35: انتقال از اينترنت 00019041 سامان به ک 6037997435482469 ش م 526811027326 ش پ 027326 | F35: 0 | G35: 2700000 | H35: 122719525 | I35: =IFERROR(__xludf.DUMMYFUNCTION("REGEXEXTRACT(E35, ""ک\s(\d{16})"")"),"6037997435482469") -> 6037997435482469 | J35: مرکز عمليات کارت(880) | K35: 40933323 | L35: -
A36: 28 | B36: 1404/07/03 | C36: 11:30:56 | D36: انتقال وجه داخلي | E36: کارمزد انتقال از اينترنت 00019041 سامان از ک 6219861085979838 ش م 526811027326 ش پ 027326 | F36: 0 | G36: 9000 | H36: 122710525 | I36: =IFERROR(__xludf.DUMMYFUNCTION("REGEXEXTRACT(E36, ""ک\s(\d{16})"")"),"6219861085979838") -> 6219861085979838 | J36: مرکز عمليات کارت(880) | K36: 40933323 | L36: -
A37: 29 | B37: 1404/07/03 | C37: 11:45:36 | D37: خريد کالا | E37: خريد کالا و خدمات از پايانه فروش 10073665 پرداخت الکترونيک سامان1 از ک 6219861085979838 ش م 85479555 | F37: 0 | G37: 2900000 | H37: 119810525 | I37: =IFERROR(__xludf.DUMMYFUNCTION("REGEXEXTRACT(E37, ""ک\s(\d{16})"")"),"6219861085979838") -> 6219861085979838 | J37: مرکز عمليات کارت(880) | K37: 40935367 | L37: -
A38: 30 | B38: 1404/07/03 | C38: 12:53:33 | D38: انتقال وجه داخلي | E38: انتقال از خودپرداز 45101693 تجارت - بين 2 به ک 5894631178646402 ش م 169326746411 ش پ 169318 | F38: 0 | G38: 10480000 | H38: 109330525 | I38: =IFERROR(__xludf.DUMMYFUNCTION("REGEXEXTRACT(E38, ""ک\s(\d{16})"")"),"5894631178646402") -> 5894631178646402 | J38: مرکز عمليات کارت(880) | K38: 30938032 | L38: -
A39: 31 | B39: 1404/07/03 | C39: 12:53:33 | D39: انتقال وجه داخلي | E39: کارمزد انتقال از خودپرداز 45101693 تجارت - بين 2 از ک 6219861085979838 ش م 169326746411 ش پ 169318 | F39: 0 | G39: 12200 | H39: 109318325 | I39: =IFERROR(__xludf.DUMMYFUNCTION("REGEXEXTRACT(E39, ""ک\s(\d{16})"")"),"6219861085979838") -> 6219861085979838 | J39: مرکز عمليات کارت(880) | K39: 30938032 | L39: -
A40: 32 | B40: 1404/07/03 | C40: 12:53:58 | D40: انتقال وجه داخلي | E40: انتقال از خودپرداز 45101693 تجارت - بين 2 به ک 6037997381658112 ش م 169326746435 ش پ 169319 | F40: 0 | G40: 9600000 | H40: 99718325 | I40: =IFERROR(__xludf.DUMMYFUNCTION("REGEXEXTRACT(E40, ""ک\s(\d{16})"")"),"6037997381658112") -> 6037997381658112 | J40: مرکز عمليات کارت(880) | K40: 30938037 | L40: -
A41: 33 | B41: 1404/07/03 | C41: 12:53:58 | D41: انتقال وجه داخلي | E41: کارمزد انتقال از خودپرداز 45101693 تجارت - بين 2 از ک 6219861085979838 ش م 169326746435 ش پ 169319 | F41: 0 | G41: 9000 | H41: 99709325 | I41: =IFERROR(__xludf.DUMMYFUNCTION("REGEXEXTRACT(E41, ""ک\s(\d{16})"")"),"6219861085979838") -> 6219861085979838 | J41: مرکز عمليات کارت(880) | K41: 30938037 | L41: -
...

Sheet Cards

Sheet Final_Data
A1: ردیف | B1: تاریخ | C1: شرح | D1: نام دارنده کارت | E1: واریز (ریال) | F1: برداشت (ریال) | G1: شماره کارت
A2: 1 | B2: 1404/07/01 | C2: انتقال وجه موبايلت از سپرده 9316.888.1579090.1 ش.پ 00001758598356202052 - محمود ابراهيميان | D2: =VLOOKUP(G2, Cards!A:B, 2, FALSE) -> #N/A | E2: 140000000 | F2: 0 | G2: =IFERROR(__xludf.DUMMYFUNCTION("REGEXEXTRACT(C2, ""ک\s(\d{16})"")"),"#N/A") -> #N/A
A3: 2 | B3: 1404/07/01 | C3: انتقال وجه موبايلت از سپرده 9316.888.1579090.1 ش.پ 00001758598963401925 - محمود ابراهيميان | D3: =VLOOKUP(G3, Cards!A:B, 2, FALSE) -> #N/A | E3: 7900000 | F3: 0 | G3: =IFERROR(__xludf.DUMMYFUNCTION("REGEXEXTRACT(C3, ""ک\s(\d{16})"")"),"#N/A") -> #N/A
A4: 3 | B4: 1404/07/01 | C4: خريد کالا و خدمات از پايانه فروش 14973164 پرداخت الکترونيک سامان1 از ک 6219861085979838 ش م 85472825 | D4: =VLOOKUP(G4, Cards!A:B, 2, FALSE) -> #N/A | E4: 0 | F4: 33435000 | G4: =IFERROR(__xludf.DUMMYFUNCTION("REGEXEXTRACT(C4, ""ک\s(\d{16})"")"),"6219861085979838") -> 6219861085979838
A5: 4 | B5: 1404/07/01 | C5: انتقال از خودپرداز 45101693 تجارت - بين 2 به ک 6037701575716284 ش م 169326543071 ش پ 169373 | D5: =VLOOKUP(G5, Cards!A:B, 2, FALSE) -> #N/A | E5: 0 | F5: 30000000 | G5: =IFERROR(__xludf.DUMMYFUNCTION("REGEXEXTRACT(C5, ""ک\s(\d{16})"")"),"6037701575716284") -> 6037701575716284
A6: 5 | B6: 1404/07/01 | C6: کارمزد انتقال از خودپرداز 45101693 تجارت - بين 2 از ک 6219861085979838 ش م 169326543071 ش پ 169373 | D6: =VLOOKUP(G6, Cards!A:B, 2, FALSE) -> #N/A | E6: 0 | F6: 15400 | G6: =IFERROR(__xludf.DUMMYFUNCTION("REGEXEXTRACT(C6, ""ک\s(\d{16})"")"),"6219861085979838") -> 6219861085979838
A7: 6 | B7: 1404/07/01 | C7: انتقال از خودپرداز 45101693 تجارت - بين 2 به ک 6104338738476148 ش م 169326543105 ش پ 169374 | D7: =VLOOKUP(G7, Cards!A:B, 2, FALSE) -> #N/A | E7: 0 | F7: 19824600 | G7: =IFERROR(__xludf.DUMMYFUNCTION("REGEXEXTRACT(C7, ""ک\s(\d{16})"")"),"6104338738476148") -> 6104338738476148
A8: 7 | B8: 1404/07/01 | C8: کارمزد انتقال از خودپرداز 45101693 تجارت - بين 2 از ک 6219861085979838 ش م 169326543105 ش پ 169374 | D8: =VLOOKUP(G8, Cards!A:B, 2, FALSE) -> #N/A | E8: 0 | F8: 12200 | G8: =IFERROR(__xludf.DUMMYFUNCTION("REGEXEXTRACT(C8, ""ک\s(\d{16})"")"),"6219861085979838") -> 6219861085979838
A9: 8 | B9: 1404/07/01 | C9: انتقال از خودپرداز 45101693 تجارت - بين 2 به ک 6274121208660688 ش م 169326543131 ش پ 169375 | D9: =VLOOKUP(G9, Cards!A:B, 2, FALSE) -> #N/A | E9: 0 | F9: 28170000 | G9: =IFERROR(__xludf.DUMMYFUNCTION("REGEXEXTRACT(C9, ""ک\s(\d{16})"")"),"6274121208660688") -> 6274121208660688
A10: 9 | B10: 1404/07/01 | C10: کارمزد انتقال از خودپرداز 45101693 تجارت - بين 2 از ک 6219861085979838 ش م 169326543131 ش پ 169375 | D10: =VLOOKUP(G10, Cards!A:B, 2, FALSE) -> #N/A | E10: 0 | F10: 15400 | G10: =IFERROR(__xludf.DUMMYFUNCTION("REGEXEXTRACT(C10, ""ک\s(\d{16})"")"),"6219861085979838") -> 6219861085979838
A11: 10 | B11: 1404/07/01 | C11: کارمزد مانده حساب از پايانه فروش 13444162 پرداخت الکترونيک سامان1 از ک 6219861085979838 ش م 85473011 | D11: =VLOOKUP(G11, Cards!A:B, 2, FALSE) -> #N/A | E11: 0 | F11: 1800 | G11: =IFERROR(__xludf.DUMMYFUNCTION("REGEXEXTRACT(C11, ""ک\s(\d{16})"")"),"6219861085979838") -> 6219861085979838
A12: 11 | B12: 1404/07/01 | C12: خريد کالا و خدمات از پايانه فروش 05465898 کارت اعتباري ايران کيش از ک 6219861085979838 ش م 658982650 | D12: =VLOOKUP(G12, Cards!A:B, 2, FALSE) -> #N/A | E12: 0 | F12: 2350000 | G12: =IFERROR(__xludf.DUMMYFUNCTION("REGEXEXTRACT(C12, ""ک\s(\d{16})"")"),"6219861085979838") -> 6219861085979838
A13: 12 | B13: 1404/07/01 | C13: انتقال از اينترنت I000MP01 تجارت - بين 2 از ک 5859831105862774 ش م 136232302991 ش پ 187674 | D13: =VLOOKUP(G13, Cards!A:B, 2, FALSE) -> #N/A | E13: 250000 | F13: 0 | G13: =IFERROR(__xludf.DUMMYFUNCTION("REGEXEXTRACT(C13, ""ک\s(\d{16})"")"),"5859831105862774") -> 5859831105862774
A14: 13 | B14: 1404/07/02 | C14: انتقال وجه موبايلت از سپرده 9316.888.1579090.1 ش.پ 00001758676641322350 - محمود ابراهيميان | D14: =VLOOKUP(G14, Cards!A:B, 2, FALSE) -> #N/A | E14: 40000000 | F14: 0 | G14: =IFERROR(__xludf.DUMMYFUNCTION("REGEXEXTRACT(C14, ""ک\s(\d{16})"")"),"#N/A") -> #N/A
A15: 14 | B15: 1404/07/02 | C15: انتقال وجه موبايلت از سپرده 9316.888.1579090.1 ش.پ 00001758676694053361 - محمود ابراهيميان | D15: =VLOOKUP(G15, Cards!A:B, 2, FALSE) -> #N/A | E15: 28000000 | F15: 0 | G15: =IFERROR(__xludf.DUMMYFUNCTION("REGEXEXTRACT(C15, ""ک\s(\d{16})"")"),"#N/A") -> #N/A
A16: 15 | B16: 1404/07/02 | C16: خريد کالا و خدمات از پايانه فروش 33562616 پرداخت الکترونيک سداد 2 از ک 6219861085979838 ش م 32885947 | D16: =VLOOKUP(G16, Cards!A:B, 2, FALSE) -> #N/A | E16: 0 | F16: 15600000 | G16: =IFERROR(__xludf.DUMMYFUNCTION("REGEXEXTRACT(C16, ""ک\s(\d{16})"")"),"6219861085979838") -> 6219861085979838
A17: 16 | B17: 1404/07/02 | C17: خريد کالا و خدمات از پايانه فروش 33795243 پرداخت الکترونيک سداد 2 از ک 6219861085979838 ش م 32885969 | D17: =VLOOKUP(G17, Cards!A:B, 2, FALSE) -> #N/A | E17: 0 | F17: 10000000 | G17: =IFERROR(__xludf.DUMMYFUNCTION("REGEXEXTRACT(C17, ""ک\s(\d{16})"")"),"6219861085979838") -> 6219861085979838
A18: 17 | B18: 1404/07/02 | C18: خريد کالا و خدمات از پايانه فروش 07027865 کارت اعتباري ايران کيش از ک 6219861085979838 ش م 278652666 | D18: =VLOOKUP(G18, Cards!A:B, 2, FALSE) -> #N/A | E18: 0 | F18: 14885000 | G18: =IFERROR(__xludf.DUMMYFUNCTION("REGEXEXTRACT(C18, ""ک\s(\d{16})"")"),"6219861085979838") -> 6219861085979838
A19: 18 | B19: 1404/07/02 | C19: خريد کالا و خدمات از پايانه فروش 99085527 مبنا کارت آريا (اينفوتک) از ک 6219861085979838 ش م 1290901 | D19: =VLOOKUP(G19, Cards!A:B, 2, FALSE) -> #N/A | E19: 0 | F19: 10375000 | G19: =IFERROR(__xludf.DUMMYFUNCTION("REGEXEXTRACT(C19, ""ک\s(\d{16})"")"),"6219861085979838") -> 6219861085979838
A20: 19 | B20: 1404/07/02 | C20: انتقال وجه بلو بانک از شبا IR810560611828005612979301 ش.پ 14042912609274 - مبينا دادگري | D20: =VLOOKUP(G20, Cards!A:B, 2, FALSE) -> #N/A | E20: 1150000 | F20: 0 | G20: =IFERROR(__xludf.DUMMYFUNCTION("REGEXEXTRACT(C20, ""ک\s(\d{16})"")"),"#N/A") -> #N/A
A21: 20 | B21: 1404/07/02 | C21: خريد کالا و خدمات از پايانه فروش 10073665 پرداخت الکترونيک سامان1 از ک 6219861085979838 ش م 85476458 | D21: =VLOOKUP(G21, Cards!A:B, 2, FALSE) -> #N/A | E21: 0 | F21: 6000000 | G21: =IFERROR(__xludf.DUMMYFUNCTION("REGEXEXTRACT(C21, ""ک\s(\d{16})"")"),"6219861085979838") -> 6219861085979838
A22: 21 | B22: 1404/07/02 | C22: کارمزد مانده حساب از پايانه فروش 13444162 پرداخت الکترونيک سامان1 از ک 6219861085979838 ش م 85476631 | D22: =VLOOKUP(G22, Cards!A:B, 2, FALSE) -> #N/A | E22: 0 | F22: 1800 | G22: =IFERROR(__xludf.DUMMYFUNCTION("REGEXEXTRACT(C22, ""ک\s(\d{16})"")"),"6219861085979838") -> 6219861085979838
A23: 22 | B23: 1404/07/02 | C23: انتقال از اينترنت I000MP01 تجارت - بين 2 از ک 5859831227346631 ش م 984881868405 ش پ 183289 | D23: =VLOOKUP(G23, Cards!A:B, 2, FALSE) -> #N/A | E23: 150000 | F23: 0 | G23: =IFERROR(__xludf.DUMMYFUNCTION("REGEXEXTRACT(C23, ""ک\s(\d{16})"")"),"5859831227346631") -> 5859831227346631
A24: 23 | B24: 1404/07/02 | C24: انتقال از اينترنت 00019041 سامان به ک 6037701642636788 ش م 526719070517 ش پ 070517 | D24: =VLOOKUP(G24, Cards!A:B, 2, FALSE) -> #N/A | E24: 0 | F24: 13200000 | G24: =IFERROR(__xludf.DUMMYFUNCTION("REGEXEXTRACT(C24, ""ک\s(\d{16})"")"),"6037701642636788") -> 6037701642636788
A25: 24 | B25: 1404/07/02 | C25: کارمزد انتقال از اينترنت 00019041 سامان از ک 6219861085979838 ش م 526719070517 ش پ 070517 | D25: =VLOOKUP(G25, Cards!A:B, 2, FALSE) -> #N/A | E25: 0 | F25: 12200 | G25: =IFERROR(__xludf.DUMMYFUNCTION("REGEXEXTRACT(C25, ""ک\s(\d{16})"")"),"6219861085979838") -> 6219861085979838
A26: 25 | B26: 1404/07/03 | C26: انتقال وجه موبايلت از سپرده 9316.888.1579090.1 ش.پ 00001758767468899694 - محمود ابراهيميان | D26: =VLOOKUP(G26, Cards!A:B, 2, FALSE) -> #N/A | E26: 72000000 | F26: 0 | G26: =IFERROR(__xludf.DUMMYFUNCTION("REGEXEXTRACT(C26, ""ک\s(\d{16})"")"),"#N/A") -> #N/A
A27: 26 | B27: 1404/07/03 | C27: خريد کالا و خدمات از پايانه فروش 33576242 پرداخت الکترونيک سداد 2 از ک 6219861085979838 ش م 32887403 | D27: =VLOOKUP(G27, Cards!A:B, 2, FALSE) -> #N/A | E27: 0 | F27: 2000000 | G27: =IFERROR(__xludf.DUMMYFUNCTION("REGEXEXTRACT(C27, ""ک\s(\d{16})"")"),"6219861085979838") -> 6219861085979838
A28: 27 | B28: 1404/07/03 | C28: انتقال از اينترنت 00019041 سامان به ک 6037997435482469 ش م 526811027326 ش پ 027326 | D28: =VLOOKUP(G28, Cards!A:B, 2, FALSE) -> #N/A | E28: 0 | F28: 2700000 | G28: =IFERROR(__xludf.DUMMYFUNCTION("REGEXEXTRACT(C28, ""ک\s(\d{16})"")"),"6037997435482469") -> 6037997435482469
A29: 28 | B29: 1404/07/03 | C29: کارمزد انتقال از اينترنت 00019041 سامان از ک 6219861085979838 ش م 526811027326 ش پ 027326 | D29: =VLOOKUP(G29, Cards!A:B, 2, FALSE) -> #N/A | E29: 0 | F29: 9000 | G29: =IFERROR(__xludf.DUMMYFUNCTION("REGEXEXTRACT(C29, ""ک\s(\d{16})"")"),"6219861085979838") -> 6219861085979838
A30: 29 | B30: 1404/07/03 | C30: خريد کالا و خدمات از پايانه فروش 10073665 پرداخت الکترونيک سامان1 از ک 6219861085979838 ش م 85479555 | D30: =VLOOKUP(G30, Cards!A:B, 2, FALSE) -> #N/A | E30: 0 | F30: 2900000 | G30: =IFERROR(__xludf.DUMMYFUNCTION("REGEXEXTRACT(C30, ""ک\s(\d{16})"")"),"6219861085979838") -> 6219861085979838
A31: 30 | B31: 1404/07/03 | C31: انتقال از خودپرداز 45101693 تجارت - بين 2 به ک 5894631178646402 ش م 169326746411 ش پ 169318 | D31: =VLOOKUP(G31, Cards!A:B, 2, FALSE) -> #N/A | E31: 0 | F31: 10480000 | G31: =IFERROR(__xludf.DUMMYFUNCTION("REGEXEXTRACT(C31, ""ک\s(\d{16})"")"),"5894631178646402") -> 5894631178646402
A32: 31 | B32: 1404/07/03 | C32: کارمزد انتقال از خودپرداز 45101693 تجارت - بين 2 از ک 6219861085979838 ش م 169326746411 ش پ 169318 | D32: =VLOOKUP(G32, Cards!A:B, 2, FALSE) -> #N/A | E32: 0 | F32: 12200 | G32: =IFERROR(__xludf.DUMMYFUNCTION("REGEXEXTRACT(C32, ""ک\s(\d{16})"")"),"6219861085979838") -> 6219861085979838
A33: 32 | B33: 1404/07/03 | C33: انتقال از خودپرداز 45101693 تجارت - بين 2 به ک 6037997381658112 ش م 169326746435 ش پ 169319 | D33: =VLOOKUP(G33, Cards!A:B, 2, FALSE) -> #N/A | E33: 0 | F33: 9600000 | G33: =IFERROR(__xludf.DUMMYFUNCTION("REGEXEXTRACT(C33, ""ک\s(\d{16})"")"),"6037997381658112") -> 6037997381658112
A34: 33 | B34: 1404/07/03 | C34: کارمزد انتقال از خودپرداز 45101693 تجارت - بين 2 از ک 6219861085979838 ش م 169326746435 ش پ 169319 | D34: =VLOOKUP(G34, Cards!A:B, 2, FALSE) -> #N/A | E34: 0 | F34: 9000 | G34: =IFERROR(__xludf.DUMMYFUNCTION("REGEXEXTRACT(C34, ""ک\s(\d{16})"")"),"6219861085979838") -> 6219861085979838
A35: 34 | B35: 1404/07/03 | C35: انتقال از خودپرداز 45101693 تجارت - بين 2 به ک 6274121208660688 ش م 169326746464 ش پ 169320 | D35: =VLOOKUP(G35, Cards!A:B, 2, FALSE) -> #N/A | E35: 0 | F35: 20430000 | G35: =IFERROR(__xludf.DUMMYFUNCTION("REGEXEXTRACT(C35, ""ک\s(\d{16})"")"),"6274121208660688") -> 6274121208660688
A36: 35 | B36: 1404/07/03 | C36: کارمزد انتقال از خودپرداز 45101693 تجارت - بين 2 از ک 6219861085979838 ش م 169326746464 ش پ 169320 | D36: =VLOOKUP(G36, Cards!A:B, 2, FALSE) -> #N/A | E36: 0 | F36: 15400 | G36: =IFERROR(__xludf.DUMMYFUNCTION("REGEXEXTRACT(C36, ""ک\s(\d{16})"")"),"6219861085979838") -> 6219861085979838
A37: 36 | B37: 1404/07/03 | C37: انتقال از خودپرداز 45101693 تجارت - بين 2 به ک 6037701642636788 ش م 169326746501 ش پ 169321 | D37: =VLOOKUP(G37, Cards!A:B, 2, FALSE) -> #N/A | E37: 0 | F37: 13200000 | G37: =IFERROR(__xludf.DUMMYFUNCTION("REGEXEXTRACT(C37, ""ک\s(\d{16})"")"),"6037701642636788") -> 6037701642636788
A38: 37 | B38: 1404/07/03 | C38: کارمزد انتقال از خودپرداز 45101693 تجارت - بين 2 از ک 6219861085979838 ش م 169326746501 ش پ 169321 | D38: =VLOOKUP(G38, Cards!A:B, 2, FALSE) -> #N/A | E38: 0 | F38: 12200 | G38: =IFERROR(__xludf.DUMMYFUNCTION("REGEXEXTRACT(C38, ""ک\s(\d{16})"")"),"6219861085979838") -> 6219861085979838
A39: 38 | B39: 1404/07/03 | C39: انتقال از خودپرداز 45101693 تجارت - بين 2 به ک 5859831103338371 ش م 169326746529 ش پ 169322 | D39: =VLOOKUP(G39, Cards!A:B, 2, FALSE) -> #N/A | E39: 0 | F39: 4000000 | G39: =IFERROR(__xludf.DUMMYFUNCTION("REGEXEXTRACT(C39, ""ک\s(\d{16})"")"),"5859831103338371") -> 5859831103338371
A40: 39 | B40: 1404/07/03 | C40: کارمزد انتقال از خودپرداز 45101693 تجارت - بين 2 از ک 6219861085979838 ش م 169326746529 ش پ 169322 | D40: =VLOOKUP(G40, Cards!A:B, 2, FALSE) -> #N/A | E40: 0 | F40: 9000 | G40: =IFERROR(__xludf.DUMMYFUNCTION("REGEXEXTRACT(C40, ""ک\s(\d{16})"")"),"6219861085979838") -> 6219861085979838
...
